[2024-07-15 14:32:05] Unhandled exception occurred:
Traceback (most recent call last):
  File "d:\Python_self_compiled_module\ErrorHook\test.py", line 5, in <module>
    with open(".\ErrorHook\README.md", "r", encoding='utf-8') as fh:
FileNotFoundError: [Errno 2] No such file or directory: '.\\ErrorHook\\README.md'
[2024-07-15 14:32:12] Unhandled exception occurred:
Traceback (most recent call last):
  File "d:\Python_self_compiled_module\ErrorHook\test.py", line 6, in <module>
    raise BaseException('I am a Error.')
BaseException: I am a Error.
[2024-07-15 14:32:33] Unhandled exception occurred:
Traceback (most recent call last):
  File "d:\Python_self_compiled_module\ErrorHook\test.py", line 6, in <module>
    raise BaseException('I am a Error.')
BaseException: I am a Error.
[2024-07-15 14:55:54] Unhandled exception occurred:
Traceback (most recent call last):
  File "d:\Python_self_compiled_module\ErrorHook\test.py", line 6, in <module>
    raise BaseException('I am a Error.')
BaseException: I am a Error.
