[2024-07-13 15:32:56] Unhandled exception occurred:
Traceback (most recent call last):
  File "d:\Python_self_compiled_module\ErrorHook.py", line 33, in <module>
    1/0
ZeroDivisionError: division by zero
[2024-07-13 15:36:44] Unhandled exception occurred:
Traceback (most recent call last):
  File "d:\Python_self_compiled_module\ErrorHook.py", line 32, in <module>
    1/0
ZeroDivisionError: division by zero
[2024-07-13 16:05:08] Unhandled exception occurred:
Traceback (most recent call last):
  File "d:\Python_self_compiled_module\ErrorHook.py", line 38, in <module>
    1/0
ZeroDivisionError: division by zero
[2024-07-13 16:05:30] Unhandled exception occurred:
Traceback (most recent call last):
  File "d:\Python_self_compiled_module\ErrorHook.py", line 38, in <module>
    1/0
ZeroDivisionError: division by zero
[2024-07-13 16:07:19] Unhandled exception occurred:
Traceback (most recent call last):
  File "d:\Python_self_compiled_module\ErrorHook.py", line 39, in <module>
    1/0
ZeroDivisionError: division by zero
[2024-07-13 16:07:32] Unhandled exception occurred:
Traceback (most recent call last):
  File "d:\Python_self_compiled_module\ErrorHook.py", line 39, in <module>
    1/0
ZeroDivisionError: division by zero
[2024-07-13 16:07:48] Unhandled exception occurred:
Traceback (most recent call last):
  File "d:\Python_self_compiled_module\ErrorHook.py", line 33, in <module>
    1/0
ZeroDivisionError: division by zero
[2024-07-13 16:12:43] Unhandled exception occurred:
Traceback (most recent call last):
  File "d:\Python_self_compiled_module\ErrorHook.py", line 37, in <module>
    1/0
ZeroDivisionError: division by zero
[2024-07-13 16:13:33] Unhandled exception occurred:
Traceback (most recent call last):
  File "d:\Python_self_compiled_module\ErrorHook.py", line 37, in <module>
    1/0
ZeroDivisionError: division by zero
[2024-07-13 16:14:06] Unhandled exception occurred:
Traceback (most recent call last):
  File "d:\Python_self_compiled_module\ErrorHook.py", line 37, in <module>
    1/0
ZeroDivisionError: division by zero
[2024-07-13 16:14:16] Unhandled exception occurred:
Traceback (most recent call last):
  File "d:\Python_self_compiled_module\ErrorHook.py", line 37, in <module>
    1/0
ZeroDivisionError: division by zero
[2024-07-13 16:14:27] Unhandled exception occurred:
Traceback (most recent call last):
  File "d:\Python_self_compiled_module\ErrorHook.py", line 37, in <module>
    1/0
ZeroDivisionError: division by zero
[2024-07-13 16:19:29] Unhandled exception occurred:
Traceback (most recent call last):
  File "d:\Python_self_compiled_module\ErrorHook.py", line 37, in <module>
    1/0
ZeroDivisionError: division by zero
[2024-07-13 16:20:09] Unhandled exception occurred:
Traceback (most recent call last):
  File "d:\Python_self_compiled_module\ErrorHook.py", line 37, in <module>
    1/0
ZeroDivisionError: division by zero
[2024-07-13 16:20:21] Unhandled exception occurred:
Traceback (most recent call last):
  File "d:\Python_self_compiled_module\ErrorHook.py", line 37, in <module>
    1/0
ZeroDivisionError: division by zero
[2024-07-13 16:21:59] Unhandled exception occurred:
Traceback (most recent call last):
  File "d:\Python_self_compiled_module\ErrorHook.py", line 38, in <module>
    1/0
ZeroDivisionError: division by zero
[2024-07-13 16:22:16] Unhandled exception occurred:
Traceback (most recent call last):
  File "d:\Python_self_compiled_module\ErrorHook.py", line 38, in <module>
    1/0
ZeroDivisionError: division by zero
[2024-07-13 16:22:34] Unhandled exception occurred:
Traceback (most recent call last):
  File "d:\Python_self_compiled_module\ErrorHook.py", line 38, in <module>
    1/0
ZeroDivisionError: division by zero
[2024-07-13 16:22:45] Unhandled exception occurred:
Traceback (most recent call last):
  File "d:\Python_self_compiled_module\ErrorHook.py", line 38, in <module>
    1/0
ZeroDivisionError: division by zero
[2024-07-13 16:22:50] Unhandled exception occurred:
Traceback (most recent call last):
  File "d:\Python_self_compiled_module\ErrorHook.py", line 38, in <module>
    1/0
ZeroDivisionError: division by zero
[2024-07-13 16:22:56] Unhandled exception occurred:
Traceback (most recent call last):
  File "d:\Python_self_compiled_module\ErrorHook.py", line 38, in <module>
    1/0
ZeroDivisionError: division by zero
[2024-07-13 16:23:24] Unhandled exception occurred:
Traceback (most recent call last):
  File "d:\Python_self_compiled_module\ErrorHook.py", line 39, in <module>
    1/0
ZeroDivisionError: division by zero
[2024-07-13 16:23:30] Unhandled exception occurred:
Traceback (most recent call last):
  File "d:\Python_self_compiled_module\ErrorHook.py", line 39, in <module>
    1/0
ZeroDivisionError: division by zero
[2024-07-13 16:23:34] Unhandled exception occurred:
Traceback (most recent call last):
  File "d:\Python_self_compiled_module\ErrorHook.py", line 39, in <module>
    1/0
ZeroDivisionError: division by zero
[2024-07-13 16:23:39] Unhandled exception occurred:
Traceback (most recent call last):
  File "d:\Python_self_compiled_module\ErrorHook.py", line 39, in <module>
    1/0
ZeroDivisionError: division by zero
[2024-07-13 16:23:47] Unhandled exception occurred:
Traceback (most recent call last):
  File "d:\Python_self_compiled_module\ErrorHook.py", line 39, in <module>
    1/0
ZeroDivisionError: division by zero
[2024-07-13 16:25:45] Unhandled exception occurred:
Traceback (most recent call last):
  File "d:\Python_self_compiled_module\ErrorHook.py", line 40, in <module>
    1/0
ZeroDivisionError: division by zero
[2024-07-13 16:25:54] Unhandled exception occurred:
Traceback (most recent call last):
  File "d:\Python_self_compiled_module\ErrorHook.py", line 40, in <module>
    1/0
ZeroDivisionError: division by zero
[2024-07-13 16:27:19] Unhandled exception occurred:
Traceback (most recent call last):
  File "d:\Python_self_compiled_module\ErrorHook.py", line 40, in <module>
    1/0
ZeroDivisionError: division by zero
[2024-07-13 16:28:14] Unhandled exception occurred:
Traceback (most recent call last):
  File "d:\Python_self_compiled_module\ErrorHook.py", line 42, in <module>
    1/0
ZeroDivisionError: division by zero
[2024-07-13 16:28:57] Unhandled exception occurred:
Traceback (most recent call last):
  File "d:\Python_self_compiled_module\ErrorHook.py", line 42, in <module>
    1/0
ZeroDivisionError: division by zero
[2024-07-13 16:29:39] Unhandled exception occurred:
Traceback (most recent call last):
  File "d:\Python_self_compiled_module\ErrorHook.py", line 42, in <module>
    1/0
ZeroDivisionError: division by zero
[2024-07-13 16:29:50] Unhandled exception occurred:
Traceback (most recent call last):
  File "d:\Python_self_compiled_module\ErrorHook.py", line 42, in <module>
    1/0
ZeroDivisionError: division by zero
[2024-07-13 16:30:12] Unhandled exception occurred:
Traceback (most recent call last):
  File "d:\Python_self_compiled_module\ErrorHook.py", line 43, in <module>
    1/0
ZeroDivisionError: division by zero
[2024-07-13 16:31:28] Unhandled exception occurred:
Traceback (most recent call last):
  File "d:\Python_self_compiled_module\ErrorHook.py", line 43, in <module>
    1/0
ZeroDivisionError: division by zero
[2024-07-13 16:33:16] Unhandled exception occurred:
Traceback (most recent call last):
  File "d:\Python_self_compiled_module\ErrorHook.py", line 47, in <module>
    1/0
ZeroDivisionError: division by zero
[2024-07-13 16:33:28] Unhandled exception occurred:
Traceback (most recent call last):
  File "d:\Python_self_compiled_module\ErrorHook.py", line 47, in <module>
    1/0
ZeroDivisionError: division by zero
[2024-07-13 16:34:37] Unhandled exception occurred:
Traceback (most recent call last):
  File "d:\Python_self_compiled_module\ErrorHook.py", line 43, in <module>
    1/0
ZeroDivisionError: division by zero
[2024-07-13 16:35:07] Unhandled exception occurred:
Traceback (most recent call last):
  File "d:\Python_self_compiled_module\ErrorHook.py", line 43, in <module>
    1/0
ZeroDivisionError: division by zero
[2024-07-13 16:35:30] Unhandled exception occurred:
Traceback (most recent call last):
  File "d:\Python_self_compiled_module\ErrorHook.py", line 43, in <module>
    1/0
ZeroDivisionError: division by zero
[2024-07-13 16:36:58] Unhandled exception occurred:
Traceback (most recent call last):
  File "d:\Python_self_compiled_module\ErrorHook.py", line 44, in <module>
    1/0
ZeroDivisionError: division by zero
[2024-07-13 16:37:48] Unhandled exception occurred:
Traceback (most recent call last):
  File "d:\Python_self_compiled_module\ErrorHook.py", line 45, in <module>
    1/0
ZeroDivisionError: division by zero
[2024-07-13 16:38:02] Unhandled exception occurred:
Traceback (most recent call last):
  File "d:\Python_self_compiled_module\ErrorHook.py", line 45, in <module>
    1/0
ZeroDivisionError: division by zero
[2024-07-13 16:54:21] Unhandled exception occurred:
Traceback (most recent call last):
  File "d:\Python_self_compiled_module\ErrorHook.py", line 46, in <module>
    1/0
ZeroDivisionError: division by zero
[2024-07-13 16:54:52] Unhandled exception occurred:
Traceback (most recent call last):
  File "d:\Python_self_compiled_module\ErrorHook.py", line 46, in <module>
    1/0
ZeroDivisionError: division by zero
[2024-07-13 16:55:14] Unhandled exception occurred:
Traceback (most recent call last):
  File "d:\Python_self_compiled_module\ErrorHook.py", line 46, in <module>
    1/0
ZeroDivisionError: division by zero
[2024-07-13 16:55:25] Unhandled exception occurred:
Traceback (most recent call last):
  File "d:\Python_self_compiled_module\ErrorHook.py", line 46, in <module>
    1/0
ZeroDivisionError: division by zero
[2024-07-13 16:55:39] Unhandled exception occurred:
Traceback (most recent call last):
  File "d:\Python_self_compiled_module\ErrorHook.py", line 46, in <module>
    1/0
ZeroDivisionError: division by zero
[2024-07-13 16:55:46] Unhandled exception occurred:
Traceback (most recent call last):
  File "d:\Python_self_compiled_module\ErrorHook.py", line 46, in <module>
    1/0
ZeroDivisionError: division by zero
[2024-07-13 16:55:54] Unhandled exception occurred:
Traceback (most recent call last):
  File "d:\Python_self_compiled_module\ErrorHook.py", line 46, in <module>
    1/0
ZeroDivisionError: division by zero
[2024-07-13 16:56:01] Unhandled exception occurred:
Traceback (most recent call last):
  File "d:\Python_self_compiled_module\ErrorHook.py", line 46, in <module>
    1/0
ZeroDivisionError: division by zero
[2024-07-13 16:56:07] Unhandled exception occurred:
Traceback (most recent call last):
  File "d:\Python_self_compiled_module\ErrorHook.py", line 46, in <module>
    1/0
ZeroDivisionError: division by zero
[2024-07-13 16:56:12] Unhandled exception occurred:
Traceback (most recent call last):
  File "d:\Python_self_compiled_module\ErrorHook.py", line 46, in <module>
    1/0
ZeroDivisionError: division by zero
[2024-07-13 16:57:49] Unhandled exception occurred:
Traceback (most recent call last):
  File "d:\Python_self_compiled_module\ErrorHook.py", line 47, in <module>
    1/0
ZeroDivisionError: division by zero
[2024-07-13 16:58:21] Unhandled exception occurred:
Traceback (most recent call last):
  File "d:\Python_self_compiled_module\ErrorHook.py", line 47, in <module>
    1/0
ZeroDivisionError: division by zero
[2024-07-13 16:58:29] Unhandled exception occurred:
Traceback (most recent call last):
  File "d:\Python_self_compiled_module\ErrorHook.py", line 47, in <module>
    1/0
ZeroDivisionError: division by zero
[2024-07-13 16:58:44] Unhandled exception occurred:
Traceback (most recent call last):
  File "d:\Python_self_compiled_module\ErrorHook.py", line 47, in <module>
    1/0
ZeroDivisionError: division by zero
[2024-07-13 16:59:00] Unhandled exception occurred:
Traceback (most recent call last):
  File "d:\Python_self_compiled_module\ErrorHook.py", line 47, in <module>
    1/0
ZeroDivisionError: division by zero
[2024-07-13 16:59:19] Unhandled exception occurred:
Traceback (most recent call last):
  File "d:\Python_self_compiled_module\ErrorHook.py", line 47, in <module>
    1/0
ZeroDivisionError: division by zero
[2024-07-13 17:28:08] Unhandled exception occurred:
Traceback (most recent call last):
  File "d:\Python_self_compiled_module\ErrorHook.py", line 47, in <module>
    1/0
ZeroDivisionError: division by zero
[2024-07-13 17:30:19] Unhandled exception occurred:
Traceback (most recent call last):
  File "d:\Python_self_compiled_module\ErrorHook.py", line 51, in <module>
    1/0
ZeroDivisionError: division by zero
[2024-07-13 17:30:38] Unhandled exception occurred:
Traceback (most recent call last):
  File "d:\Python_self_compiled_module\ErrorHook.py", line 51, in <module>
    1/0
ZeroDivisionError: division by zero
[2024-07-13 17:31:49] Unhandled exception occurred:
Traceback (most recent call last):
  File "d:\Python_self_compiled_module\ErrorHook.py", line 51, in <module>
    1/0
ZeroDivisionError: division by zero
[2024-07-13 17:33:31] Unhandled exception occurred:
Traceback (most recent call last):
  File "d:\Python_self_compiled_module\ErrorHook.py", line 56, in <module>
    1/0
ZeroDivisionError: division by zero
[2024-07-13 17:33:57] Unhandled exception occurred:
Traceback (most recent call last):
  File "d:\Python_self_compiled_module\ErrorHook.py", line 56, in <module>
    1/0
ZeroDivisionError: division by zero
[2024-07-13 17:35:22] Unhandled exception occurred:
Traceback (most recent call last):
  File "d:\Python_self_compiled_module\ErrorHook.py", line 56, in <module>
    1/0
ZeroDivisionError: division by zero
[2024-07-13 17:35:46] Unhandled exception occurred:
Traceback (most recent call last):
  File "d:\Python_self_compiled_module\ErrorHook.py", line 56, in <module>
    1/0
ZeroDivisionError: division by zero
[2024-07-13 17:37:48] Unhandled exception occurred:
Traceback (most recent call last):
  File "d:\Python_self_compiled_module\ErrorHook.py", line 55, in <module>
    1/0
ZeroDivisionError: division by zero
[2024-07-13 17:41:04] Unhandled exception occurred:
Traceback (most recent call last):
  File "d:\Python_self_compiled_module\ErrorHook.py", line 59, in <module>
    1/0
ZeroDivisionError: division by zero
[2024-07-13 17:41:43] Unhandled exception occurred:
Traceback (most recent call last):
  File "d:\Python_self_compiled_module\ErrorHook.py", line 59, in <module>
    1/0
ZeroDivisionError: division by zero
[2024-07-13 17:43:01] Unhandled exception occurred:
Traceback (most recent call last):
  File "d:\Python_self_compiled_module\test.py", line 3, in <module>
    1/0
ZeroDivisionError: division by zero
[2024-07-13 17:43:18] Unhandled exception occurred:
Traceback (most recent call last):
  File "d:\Python_self_compiled_module\test.py", line 3, in <module>
    print(a)
NameError: name 'a' is not defined
[2024-07-13 17:44:37] Unhandled exception occurred:
Traceback (most recent call last):
  File "d:\Python_self_compiled_module\ErrorHook.py", line 59, in <module>
    1/0
ZeroDivisionError: division by zero
[2024-07-13 17:44:42] Unhandled exception occurred:
Traceback (most recent call last):
  File "d:\Python_self_compiled_module\test.py", line 3, in <module>
    print(a)
NameError: name 'a' is not defined
[2024-07-13 17:45:05] Unhandled exception occurred:
Traceback (most recent call last):
  File "d:\Python_self_compiled_module\test.py", line 3, in <module>
    raise BaseException('...tx')
BaseException: ...tx
[2024-07-13 17:45:17] Unhandled exception occurred:
Traceback (most recent call last):
  File "d:\Python_self_compiled_module\test.py", line 3, in <module>
    raise BaseException('...tx')
BaseException: ...tx
[2024-07-13 17:51:11] Unhandled exception occurred:
Traceback (most recent call last):
  File "d:\Python_self_compiled_module\test.py", line 4, in <module>
    print(1/0)
ZeroDivisionError: division by zero
[2024-07-13 17:53:01] Unhandled exception occurred:
Traceback (most recent call last):
  File "d:\Python_self_compiled_module\test.py", line 4, in <module>
    print(1/0)
ZeroDivisionError: division by zero
[2024-07-13 17:53:09] Unhandled exception occurred:
Traceback (most recent call last):
  File "d:\Python_self_compiled_module\test.py", line 5, in <module>
    print(a)
NameError: name 'a' is not defined
[2024-07-13 17:53:16] Unhandled exception occurred:
Traceback (most recent call last):
  File "d:\Python_self_compiled_module\test.py", line 6, in <module>
    raise BaseException('...tx')
BaseException: ...tx
[2024-07-13 17:55:10] Unhandled exception occurred:
Traceback (most recent call last):
  File "d:\Python_self_compiled_module\test.py", line 4, in <module>
    print(1/0)
ZeroDivisionError: division by zero
[2024-07-13 17:56:14] Unhandled exception occurred:
Traceback (most recent call last):
  File "d:\Python_self_compiled_module\test.py", line 4, in <module>
    print(1/0)
ZeroDivisionError: division by zero
[2024-07-13 17:56:21] Unhandled exception occurred:
Traceback (most recent call last):
  File "d:\Python_self_compiled_module\test.py", line 5, in <module>
    print(a)
NameError: name 'a' is not defined
[2024-07-13 17:56:29] Unhandled exception occurred:
Traceback (most recent call last):
  File "d:\Python_self_compiled_module\test.py", line 6, in <module>
    raise BaseException('...tx')
BaseException: ...tx
[2024-07-13 17:56:41] Unhandled exception occurred:
Traceback (most recent call last):
  File "d:\Python_self_compiled_module\test.py", line 6, in <module>
    raise BaseException('...tx')
BaseException: ...tx
[2024-07-13 18:30:29] Unhandled exception occurred:
Traceback (most recent call last):
  File "d:\Python_self_compiled_module\ErrorHook.py", line 68, in <module>
    1/0
ZeroDivisionError: division by zero
[2024-07-13 21:21:23] Unhandled exception occurred:
Traceback (most recent call last):
  File "d:\Python_self_compiled_module\ErrorHook.py", line 68, in <module>
    1/0
ZeroDivisionError: division by zero
[2024-07-13 21:21:46] Unhandled exception occurred:
Traceback (most recent call last):
  File "d:\Python_self_compiled_module\ErrorHook.py", line 68, in <module>
    1/0
ZeroDivisionError: division by zero
[2024-07-15 07:56:55] Unhandled exception occurred:
Traceback (most recent call last):
  File "d:\Python_self_compiled_module\test.py", line 6, in <module>
    raise BaseException('...tx')
BaseException: ...tx
[2024-07-15 11:26:07] Unhandled exception occurred:
Traceback (most recent call last):
  File "d:\Python_self_compiled_module\ErrorHook\test.py", line 5, in <module>
    with open(".\ErrorHook\README.md", "r", encoding='utf-8') as fh:
FileNotFoundError: [Errno 2] No such file or directory: '.\\ErrorHook\\README.md'
